Workbook

Sheet README
A1: Process Group Roadmap — data template
A2: Fill in the yellow cells. White cells are formulas — leave them alone.
A4: Sheets, in the order to fill them
A5: 1. Sprints — your sprint calendar. Add or delete rows to match how far you have actually planned.
A6: 2. People — everyone who owns work. Initials become the avatar on the roadmap.
A7: 3. ProcessGroups — the workflows being redesigned. One row each. This is the unit of the roadmap.
A8: 4. Activities — the bars. One row per piece of work.
A9: 5. Milestones — transfers and commitments only. See the list on the Lists sheet.
A11: Rules worth knowing before you start
A12: • Horizon is a property of an ACTIVITY, not of a process group. The same process group can carry
A13: future-state, MVP and PoC work at once — give it one row per activity and set the horizon on each.
A14: • A UX coverage gap is computed by the roadmap, not here: any sprint where a process group has
... A21: Grey italic = an example row. Delete the example rows before you use this for real.

Sheet Lists
A1: Horizon | B1: Track | C1: MilestoneType | D1: ActivityType | E1: DesignStage
A2: Future-State Discovery | B2: Product owner | C2: Discovery to backlog | D2: Research | E2: Discover
A3: MVP Delivery | B3: UX | C3: Requirements baselined | D3: Workshop | E3: Discover
A4: Innovation & PoC | B4: Enablement | C4: Design handoff to engineering | D4: Artefact | E4: Define
A5: Operational Enablement | C5: Stakeholder demo | D5: Requirements | E5: Define
C6: UAT start | D6: Sign-off | E6: Define
C7: PoC gate decision | D7: Backlog | E7: Define
C8: Graduates to MVP delivery | D8: Framing | E8: Define
C9: Go-live | D9: Concept | E9: Design
C10: Legacy freeze | D10: Design | E10: Design
C11: Steering group | D11: Spike | E11: Design
D12: Testing | E12: Validate
D13: UAT | E13: Validate
D14: Gate | E14: Validate
D15: Handoff | E15: Deliver
D16: Release | E16: Deliver
D17: Provisioning | E17: Deliver
D18: Procurement | E18: Enable
D19: Access | E19: Enable
D20: Recruiting | E20: Enable
D22: Type drives Design stage. Add a pair here to add a stage.

Sheet Sprints
A1: Sprint | B1: Start date | C1: End date | D1: Reduced capacity? | E1: Note
A2: S1 | B2: 2026-09-28 | C2: 2026-10-09 | D2: No
A3: S2 | B3: 2026-10-12 | C3: 2026-10-23 | D3: No
A4: S3 | B4: 2026-10-26 | C4: 2026-11-06 | D4: No
A5: S4 | B5: 2026-11-09 | C5: 2026-11-20 | D5: No
A6: S5 | B6: 2026-11-23 | C6: 2026-12-04 | D6: No
A7: S6 | B7: 2026-12-07 | C7: 2026-12-18 | D7: No
A8: S7 | B8: 2026-12-21 | C8: 2027-01-01 | D8: Yes | E8: Holiday period — plan nothing with a hard commitment here.
A9: S8 | B9: 2027-01-04 | C9: 2027-01-15 | D9: No
A10: S9 | B10: 2027-01-18 | C10: 2027-01-29 | D10: No
A11: S10 | B11: 2027-02-01 | C11: 2027-02-12 | D11: No
A12: S11 | B12: 2027-02-15 | C12: 2027-02-26 | D12: No
A13: S12 | B13: 2027-03-01 | C13: 2027-03-12 | D13: No
A14: S13 | B14: 2027-03-15 | C14: 2027-03-26 | D14: No

Sheet People
A1: Initials | B1: Full name | C1: Role | D1: Team
A2: DW | B2: Dana Whitfield | C2: Product owner | D2: EXAMPLE — delete
A3: TO | B3: Tom Okafor | C3: Researcher | D3: EXAMPLE — delete
A4: LB | B4: Lena Brandt | C4: Designer | D4: EXAMPLE — delete

Sheet ProcessGroups
A1: ID | B1: Process group | C1: Owning product owner | D1: Notes
A2: PG-01 | B2: Work Intake & Triage | C2: Dana Whitfield | D2: EXAMPLE — delete before use

Sheet Activities
A1: Process group ID | B1: Horizon | C1: Track | D1: Activity | E1: Type | F1: Owner | G1: Start sprint | H1: Sprints long | I1: Start date | J1: End date | K1: Design stage
A2: PG-01 | B2: Future-State Discovery | C2: UX | D2: Generative research | E2: Research | F2: Tom Okafor | G2: S1 | H2: 3 | I2: =IFERROR(INDEX(Sprints!$B$2:$B$60,MATCH(G2,Sprints!$A$2:$A$60,0)),"") | J2: =IFERROR(INDEX(Sprints!$C$2:$C$60,MATCH(G2,Sprints!$A$2:$A$60,0)+H2-1),"") | K2: =IFERROR(INDEX(Lists!$E$2:$E$40,MATCH(E2,Lists!$D$2:$D$40,0)),"")
A3: PG-01 | B3: MVP Delivery | C3: Product owner | D3: Acceptance criteria | E3: Sign-off | F3: Dana Whitfield | G3: S5 | H3: 2 | I3: =IFERROR(INDEX(Sprints!$B$2:$B$60,MATCH(G3,Sprints!$A$2:$A$60,0)),"") | J3: =IFERROR(INDEX(Sprints!$C$2:$C$60,MATCH(G3,Sprints!$A$2:$A$60,0)+H3-1),"") | K3: =IFERROR(INDEX(Lists!$E$2:$E$40,MATCH(E3,Lists!$D$2:$D$40,0)),"")
A4: PG-01 | B4: MVP Delivery | C4: UX | D4: Wireframes | E4: Design | F4: Lena Brandt | G4: S5 | H4: 2 | I4: =IFERROR(INDEX(Sprints!$B$2:$B$60,MATCH(G4,Sprints!$A$2:$A$60,0)),"") | J4: =IFERROR(INDEX(Sprints!$C$2:$C$60,MATCH(G4,Sprints!$A$2:$A$60,0)+H4-1),"") | K4: =IFERROR(INDEX(Lists!$E$2:$E$40,MATCH(E4,Lists!$D$2:$D$40,0)),"")
I5: =IFERROR(INDEX(Sprints!$B$2:$B$60,MATCH(G5,Sprints!$A$2:$A$60,0)),"") | J5: =IFERROR(INDEX(Sprints!$C$2:$C$60,MATCH(G5,Sprints!$A$2:$A$60,0)+H5-1),"") | K5: =IFERROR(INDEX(Lists!$E$2:$E$40,MATCH(E5,Lists!$D$2:$D$40,0)),"")
I6: =IFERROR(INDEX(Sprints!$B$2:$B$60,MATCH(G6,Sprints!$A$2:$A$60,0)),"") | J6: =IFERROR(INDEX(Sprints!$C$2:$C$60,MATCH(G6,Sprints!$A$2:$A$60,0)+H6-1),"") | K6: =IFERROR(INDEX(Lists!$E$2:$E$40,MATCH(E6,Lists!$D$2:$D$40,0)),"")
I7: =IFERROR(INDEX(Sprints!$B$2:$B$60,MATCH(G7,Sprints!$A$2:$A$60,0)),"") | J7: =IFERROR(INDEX(Sprints!$C$2:$C$60,MATCH(G7,Sprints!$A$2:$A$60,0)+H7-1),"") | K7: =IFERROR(INDEX(Lists!$E$2:$E$40,MATCH(E7,Lists!$D$2:$D$40,0)),"")
I8: =IFERROR(INDEX(Sprints!$B$2:$B$60,MATCH(G8,Sprints!$A$2:$A$60,0)),"") | J8: =IFERROR(INDEX(Sprints!$C$2:$C$60,MATCH(G8,Sprints!$A$2:$A$60,0)+H8-1),"") | K8: =IFERROR(INDEX(Lists!$E$2:$E$40,MATCH(E8,Lists!$D$2:$D$40,0)),"")
I9: =IFERROR(INDEX(Sprints!$B$2:$B$60,MATCH(G9,Sprints!$A$2:$A$60,0)),"") | J9: =IFERROR(INDEX(Sprints!$C$2:$C$60,MATCH(G9,Sprints!$A$2:$A$60,0)+H9-1),"") | K9: =IFERROR(INDEX(Lists!$E$2:$E$40,MATCH(E9,Lists!$D$2:$D$40,0)),"")
I10: =IFERROR(INDEX(Sprints!$B$2:$B$60,MATCH(G10,Sprints!$A$2:$A$60,0)),"") | J10: =IFERROR(INDEX(Sprints!$C$2:$C$60,MATCH(G10,Sprints!$A$2:$A$60,0)+H10-1),"") | K10: =IFERROR(INDEX(Lists!$E$2:$E$40,MATCH(E10,Lists!$D$2:$D$40,0)),"")
I11: =IFERROR(INDEX(Sprints!$B$2:$B$60,MATCH(G11,Sprints!$A$2:$A$60,0)),"") | J11: =IFERROR(INDEX(Sprints!$C$2:$C$60,MATCH(G11,Sprints!$A$2:$A$60,0)+H11-1),"") | K11: =IFERROR(INDEX(Lists!$E$2:$E$40,MATCH(E11,Lists!$D$2:$D$40,0)),"")
I12: =IFERROR(INDEX(Sprints!$B$2:$B$60,MATCH(G12,Sprints!$A$2:$A$60,0)),"") | J12: =IFERROR(INDEX(Sprints!$C$2:$C$60,MATCH(G12,Sprints!$A$2:$A$60,0)+H12-1),"") | K12: =IFERROR(INDEX(Lists!$E$2:$E$40,MATCH(E12,Lists!$D$2:$D$40,0)),"")
I13: =IFERROR(INDEX(Sprints!$B$2:$B$60,MATCH(G13,Sprints!$A$2:$A$60,0)),"") | J13: =IFERROR(INDEX(Sprints!$C$2:$C$60,MATCH(G13,Sprints!$A$2:$A$60,0)+H13-1),"") | K13: =IFERROR(INDEX(Lists!$E$2:$E$40,MATCH(E13,Lists!$D$2:$D$40,0)),"")
I14: =IFERROR(INDEX(Sprints!$B$2:$B$60,MATCH(G14,Sprints!$A$2:$A$60,0)),"") | J14: =IFERROR(INDEX(Sprints!$C$2:$C$60,MATCH(G14,Sprints!$A$2:$A$60,0)+H14-1),"") | K14: =IFERROR(INDEX(Lists!$E$2:$E$40,MATCH(E14,Lists!$D$2:$D$40,0)),"")
I15: =IFERROR(INDEX(Sprints!$B$2:$B$60,MATCH(G15,Sprints!$A$2:$A$60,0)),"") | J15: =IFERROR(INDEX(Sprints!$C$2:$C$60,MATCH(G15,Sprints!$A$2:$A$60,0)+H15-1),"") | K15: =IFERROR(INDEX(Lists!$E$2:$E$40,MATCH(E15,Lists!$D$2:$D$40,0)),"")
I16: =IFERROR(INDEX(Sprints!$B$2:$B$60,MATCH(G16,Sprints!$A$2:$A$60,0)),"") | J16: =IFERROR(INDEX(Sprints!$C$2:$C$60,MATCH(G16,Sprints!$A$2:$A$60,0)+H16-1),"") | K16: =IFERROR(INDEX(Lists!$E$2:$E$40,MATCH(E16,Lists!$D$2:$D$40,0)),"")
... I161: =IFERROR(INDEX(Sprints!$B$2:$B$60,MATCH(G161,Sprints!$A$2:$A$60,0)),"") | J161: =IFERROR(INDEX(Sprints!$C$2:$C$60,MATCH(G161,Sprints!$A$2:$A$60,0)+H161-1),"") | K161: =IFERROR(INDEX(Lists!$E$2:$E$40,MATCH(E161,Lists!$D$2:$D$40,0)),"")

Sheet Milestones
A1: Scope | B1: Process group ID | C1: Sprint | D1: Milestone type | E1: Name | F1: Date
A2: Process group | B2: PG-01 | C2: S4 | D2: Discovery to backlog | E2: Synthesis to 6 backlog items — EXAMPLE | F2: =IFERROR(INDEX(Sprints!$C$2:$C$60,MATCH(C2,Sprints!$A$2:$A$60,0)),"")
F3: =IFERROR(INDEX(Sprints!$C$2:$C$60,MATCH(C3,Sprints!$A$2:$A$60,0)),"")
F4: =IFERROR(INDEX(Sprints!$C$2:$C$60,MATCH(C4,Sprints!$A$2:$A$60,0)),"")
F5: =IFERROR(INDEX(Sprints!$C$2:$C$60,MATCH(C5,Sprints!$A$2:$A$60,0)),"")
F6: =IFERROR(INDEX(Sprints!$C$2:$C$60,MATCH(C6,Sprints!$A$2:$A$60,0)),"")
F7: =IFERROR(INDEX(Sprints!$C$2:$C$60,MATCH(C7,Sprints!$A$2:$A$60,0)),"")
F8: =IFERROR(INDEX(Sprints!$C$2:$C$60,MATCH(C8,Sprints!$A$2:$A$60,0)),"")
F9: =IFERROR(INDEX(Sprints!$C$2:$C$60,MATCH(C9,Sprints!$A$2:$A$60,0)),"")
F10: =IFERROR(INDEX(Sprints!$C$2:$C$60,MATCH(C10,Sprints!$A$2:$A$60,0)),"")
F11: =IFERROR(INDEX(Sprints!$C$2:$C$60,MATCH(C11,Sprints!$A$2:$A$60,0)),"")
F12: =IFERROR(INDEX(Sprints!$C$2:$C$60,MATCH(C12,Sprints!$A$2:$A$60,0)),"")
F13: =IFERROR(INDEX(Sprints!$C$2:$C$60,MATCH(C13,Sprints!$A$2:$A$60,0)),"")
F14: =IFERROR(INDEX(Sprints!$C$2:$C$60,MATCH(C14,Sprints!$A$2:$A$60,0)),"")
... F81: =IFERROR(INDEX(Sprints!$C$2:$C$60,MATCH(C81,Sprints!$A$2:$A$60,0)),"")

Sheet Summary
A1: Process group | B1: PO activities | C1: UX activities | D1: Total | E1: Milestones | F1: Horizons used
A2: =IFERROR(INDEX(ProcessGroups!$B$2:$B$80,2-1),"") | B2: =IF($A2="","",COUNTIFS(Activities!$A$2:$A$161,INDEX(ProcessGroups!$A$2:$A$80,2-1),Activities!$C$2:$C$161,"Product owner")) | C2: =IF($A2="","",COUNTIFS(Activities!$A$2:$A$161,INDEX(ProcessGroups!$A$2:$A$80,2-1),Activities!$C$2:$C$161,"UX")) | D2: =IF($A2="","",B2+C2) | E2: =IF($A2="","",COUNTIF(Milestones!$B$2:$B$81,INDEX(ProcessGroups!$A$2:$A$80,2-1))) | F2: =IF($A2="","",SUMPRODUCT((COUNTIFS(Activities!$A$2:$A$161,INDEX(ProcessGroups!$A$2:$A$80,2-1),Activities!$B$2:$B$161,Lists!$A$2:$A$5)>0)*1))
A3: =IFERROR(INDEX(ProcessGroups!$B$2:$B$80,3-1),"") | B3: =IF($A3="","",COUNTIFS(Activities!$A$2:$A$161,INDEX(ProcessGroups!$A$2:$A$80,3-1),Activities!$C$2:$C$161,"Product owner")) | C3: =IF($A3="","",COUNTIFS(Activities!$A$2:$A$161,INDEX(ProcessGroups!$A$2:$A$80,3-1),Activities!$C$2:$C$161,"UX")) | D3: =IF($A3="","",B3+C3) | E3: =IF($A3="","",COUNTIF(Milestones!$B$2:$B$81,INDEX(ProcessGroups!$A$2:$A$80,3-1))) | F3: =IF($A3="","",SUMPRODUCT((COUNTIFS(Activities!$A$2:$A$161,INDEX(ProcessGroups!$A$2:$A$80,3-1),Activities!$B$2:$B$161,Lists!$A$2:$A$5)>0)*1))
A4: =IFERROR(INDEX(ProcessGroups!$B$2:$B$80,4-1),"") | B4: =IF($A4="","",COUNTIFS(Activities!$A$2:$A$161,INDEX(ProcessGroups!$A$2:$A$80,4-1),Activities!$C$2:$C$161,"Product owner")) | C4: =IF($A4="","",COUNTIFS(Activities!$A$2:$A$161,INDEX(ProcessGroups!$A$2:$A$80,4-1),Activities!$C$2:$C$161,"UX")) | D4: =IF($A4="","",B4+C4) | E4: =IF($A4="","",COUNTIF(Milestones!$B$2:$B$81,INDEX(ProcessGroups!$A$2:$A$80,4-1))) | F4: =IF($A4="","",SUMPRODUCT((COUNTIFS(Activities!$A$2:$A$161,INDEX(ProcessGroups!$A$2:$A$80,4-1),Activities!$B$2:$B$161,Lists!$A$2:$A$5)>0)*1))
A5: =IFERROR(INDEX(ProcessGroups!$B$2:$B$80,5-1),"") | B5: =IF($A5="","",COUNTIFS(Activities!$A$2:$A$161,INDEX(ProcessGroups!$A$2:$A$80,5-1),Activities!$C$2:$C$161,"Product owner")) | C5: =IF($A5="","",COUNTIFS(Activities!$A$2:$A$161,INDEX(ProcessGroups!$A$2:$A$80,5-1),Activities!$C$2:$C$161,"UX")) | D5: =IF($A5="","",B5+C5) | E5: =IF($A5="","",COUNTIF(Milestones!$B$2:$B$81,INDEX(ProcessGroups!$A$2:$A$80,5-1))) | F5: =IF($A5="","",SUMPRODUCT((COUNTIFS(Activities!$A$2:$A$161,INDEX(ProcessGroups!$A$2:$A$80,5-1),Activities!$B$2:$B$161,Lists!$A$2:$A$5)>0)*1))
A6: =IFERROR(INDEX(ProcessGroups!$B$2:$B$80,6-1),"") | B6: =IF($A6="","",COUNTIFS(Activities!$A$2:$A$161,INDEX(ProcessGroups!$A$2:$A$80,6-1),Activities!$C$2:$C$161,"Product owner")) | C6: =IF($A6="","",COUNTIFS(Activities!$A$2:$A$161,INDEX(ProcessGroups!$A$2:$A$80,6-1),Activities!$C$2:$C$161,"UX")) | D6: =IF($A6="","",B6+C6) | E6: =IF($A6="","",COUNTIF(Milestones!$B$2:$B$81,INDEX(ProcessGroups!$A$2:$A$80,6-1))) | F6: =IF($A6="","",SUMPRODUCT((COUNTIFS(Activities!$A$2:$A$161,INDEX(ProcessGroups!$A$2:$A$80,6-1),Activities!$B$2:$B$161,Lists!$A$2:$A$5)>0)*1))
A7: =IFERROR(INDEX(ProcessGroups!$B$2:$B$80,7-1),"") | B7: =IF($A7="","",COUNTIFS(Activities!$A$2:$A$161,INDEX(ProcessGroups!$A$2:$A$80,7-1),Activities!$C$2:$C$161,"Product owner")) | C7: =IF($A7="","",COUNTIFS(Activities!$A$2:$A$161,INDEX(ProcessGroups!$A$2:$A$80,7-1),Activities!$C$2:$C$161,"UX")) | D7: =IF($A7="","",B7+C7) | E7: =IF($A7="","",COUNTIF(Milestones!$B$2:$B$81,INDEX(ProcessGroups!$A$2:$A$80,7-1))) | F7: =IF($A7="","",SUMPRODUCT((COUNTIFS(Activities!$A$2:$A$161,INDEX(ProcessGroups!$A$2:$A$80,7-1),Activities!$B$2:$B$161,Lists!$A$2:$A$5)>0)*1))
A8: =IFERROR(INDEX(ProcessGroups!$B$2:$B$80,8-1),"") | B8: =IF($A8="","",COUNTIFS(Activities!$A$2:$A$161,INDEX(ProcessGroups!$A$2:$A$80,8-1),Activities!$C$2:$C$161,"Product owner")) | C8: =IF($A8="","",COUNTIFS(Activities!$A$2:$A$161,INDEX(ProcessGroups!$A$2:$A$80,8-1),Activities!$C$2:$C$161,"UX")) | D8: =IF($A8="","",B8+C8) | E8: =IF($A8="","",COUNTIF(Milestones!$B$2:$B$81,INDEX(ProcessGroups!$A$2:$A$80,8-1))) | F8: =IF($A8="","",SUMPRODUCT((COUNTIFS(Activities!$A$2:$A$161,INDEX(ProcessGroups!$A$2:$A$80,8-1),Activities!$B$2:$B$161,Lists!$A$2:$A$5)>0)*1))
A9: =IFERROR(INDEX(ProcessGroups!$B$2:$B$80,9-1),"") | B9: =IF($A9="","",COUNTIFS(Activities!$A$2:$A$161,INDEX(ProcessGroups!$A$2:$A$80,9-1),Activities!$C$2:$C$161,"Product owner")) | C9: =IF($A9="","",COUNTIFS(Activities!$A$2:$A$161,INDEX(ProcessGroups!$A$2:$A$80,9-1),Activities!$C$2:$C$161,"UX")) | D9: =IF($A9="","",B9+C9) | E9: =IF($A9="","",COUNTIF(Milestones!$B$2:$B$81,INDEX(ProcessGroups!$A$2:$A$80,9-1))) | F9: =IF($A9="","",SUMPRODUCT((COUNTIFS(Activities!$A$2:$A$161,INDEX(ProcessGroups!$A$2:$A$80,9-1),Activities!$B$2:$B$161,Lists!$A$2:$A$5)>0)*1))
A10: =IFERROR(INDEX(ProcessGroups!$B$2:$B$80,10-1),"") | B10: =IF($A10="","",COUNTIFS(Activities!$A$2:$A$161,INDEX(ProcessGroups!$A$2:$A$80,10-1),Activities!$C$2:$C$161,"Product owner")) | C10: =IF($A10="","",COUNTIFS(Activities!$A$2:$A$161,INDEX(ProcessGroups!$A$2:$A$80,10-1),Activities!$C$2:$C$161,"UX")) | D10: =IF($A10="","",B10+C10) | E10: =IF($A10="","",COUNTIF(Milestones!$B$2:$B$81,INDEX(ProcessGroups!$A$2:$A$80,10-1))) | F10: =IF($A10="","",SUMPRODUCT((COUNTIFS(Activities!$A$2:$A$161,INDEX(ProcessGroups!$A$2:$A$80,10-1),Activities!$B$2:$B$161,Lists!$A$2:$A$5)>0)*1))
A11: =IFERROR(INDEX(ProcessGroups!$B$2:$B$80,11-1),"") | B11: =IF($A11="","",COUNTIFS(Activities!$A$2:$A$161,INDEX(ProcessGroups!$A$2:$A$80,11-1),Activities!$C$2:$C$161,"Product owner")) | C11: =IF($A11="","",COUNTIFS(Activities!$A$2:$A$161,INDEX(ProcessGroups!$A$2:$A$80,11-1),Activities!$C$2:$C$161,"UX")) | D11: =IF($A11="","",B11+C11) | E11: =IF($A11="","",COUNTIF(Milestones!$B$2:$B$81,INDEX(ProcessGroups!$A$2:$A$80,11-1))) | F11: =IF($A11="","",SUMPRODUCT((COUNTIFS(Activities!$A$2:$A$161,INDEX(ProcessGroups!$A$2:$A$80,11-1),Activities!$B$2:$B$161,Lists!$A$2:$A$5)>0)*1))
A12: =IFERROR(INDEX(ProcessGroups!$B$2:$B$80,12-1),"") | B12: =IF($A12="","",COUNTIFS(Activities!$A$2:$A$161,INDEX(ProcessGroups!$A$2:$A$80,12-1),Activities!$C$2:$C$161,"Product owner")) | C12: =IF($A12="","",COUNTIFS(Activities!$A$2:$A$161,INDEX(ProcessGroups!$A$2:$A$80,12-1),Activities!$C$2:$C$161,"UX")) | D12: =IF($A12="","",B12+C12) | E12: =IF($A12="","",COUNTIF(Milestones!$B$2:$B$81,INDEX(ProcessGroups!$A$2:$A$80,12-1))) | F12: =IF($A12="","",SUMPRODUCT((COUNTIFS(Activities!$A$2:$A$161,INDEX(ProcessGroups!$A$2:$A$80,12-1),Activities!$B$2:$B$161,Lists!$A$2:$A$5)>0)*1))
A13: =IFERROR(INDEX(ProcessGroups!$B$2:$B$80,13-1),"") | B13: =IF($A13="","",COUNTIFS(Activities!$A$2:$A$161,INDEX(ProcessGroups!$A$2:$A$80,13-1),Activities!$C$2:$C$161,"Product owner")) | C13: =IF($A13="","",COUNTIFS(Activities!$A$2:$A$161,INDEX(ProcessGroups!$A$2:$A$80,13-1),Activities!$C$2:$C$161,"UX")) | D13: =IF($A13="","",B13+C13) | E13: =IF($A13="","",COUNTIF(Milestones!$B$2:$B$81,INDEX(ProcessGroups!$A$2:$A$80,13-1))) | F13: =IF($A13="","",SUMPRODUCT((COUNTIFS(Activities!$A$2:$A$161,INDEX(ProcessGroups!$A$2:$A$80,13-1),Activities!$B$2:$B$161,Lists!$A$2:$A$5)>0)*1))
A14: =IFERROR(INDEX(ProcessGroups!$B$2:$B$80,14-1),"") | B14: =IF($A14="","",COUNTIFS(Activities!$A$2:$A$161,INDEX(ProcessGroups!$A$2:$A$80,14-1),Activities!$C$2:$C$161,"Product owner")) | C14: =IF($A14="","",COUNTIFS(Activities!$A$2:$A$161,INDEX(ProcessGroups!$A$2:$A$80,14-1),Activities!$C$2:$C$161,"UX")) | D14: =IF($A14="","",B14+C14) | E14: =IF($A14="","",COUNTIF(Milestones!$B$2:$B$81,INDEX(ProcessGroups!$A$2:$A$80,14-1))) | F14: =IF($A14="","",SUMPRODUCT((COUNTIFS(Activities!$A$2:$A$161,INDEX(ProcessGroups!$A$2:$A$80,14-1),Activities!$B$2:$B$161,Lists!$A$2:$A$5)>0)*1))
A15: =IFERROR(INDEX(ProcessGroups!$B$2:$B$80,15-1),"") | B15: =IF($A15="","",COUNTIFS(Activities!$A$2:$A$161,INDEX(ProcessGroups!$A$2:$A$80,15-1),Activities!$C$2:$C$161,"Product owner")) | C15: =IF($A15="","",COUNTIFS(Activities!$A$2:$A$161,INDEX(ProcessGroups!$A$2:$A$80,15-1),Activities!$C$2:$C$161,"UX")) | D15: =IF($A15="","",B15+C15) | E15: =IF($A15="","",COUNTIF(Milestones!$B$2:$B$81,INDEX(ProcessGroups!$A$2:$A$80,15-1))) | F15: =IF($A15="","",SUMPRODUCT((COUNTIFS(Activities!$A$2:$A$161,INDEX(ProcessGroups!$A$2:$A$80,15-1),Activities!$B$2:$B$161,Lists!$A$2:$A$5)>0)*1))
A16: =IFERROR(INDEX(ProcessGroups!$B$2:$B$80,16-1),"") | B16: =IF($A16="","",COUNTIFS(Activities!$A$2:$A$161,INDEX(ProcessGroups!$A$2:$A$80,16-1),Activities!$C$2:$C$161,"Product owner")) | C16: =IF($A16="","",COUNTIFS(Activities!$A$2:$A$161,INDEX(ProcessGroups!$A$2:$A$80,16-1),Activities!$C$2:$C$161,"UX")) | D16: =IF($A16="","",B16+C16) | E16: =IF($A16="","",COUNTIF(Milestones!$B$2:$B$81,INDEX(ProcessGroups!$A$2:$A$80,16-1))) | F16: =IF($A16="","",SUMPRODUCT((COUNTIFS(Activities!$A$2:$A$161,INDEX(ProcessGroups!$A$2:$A$80,16-1),Activities!$B$2:$B$161,Lists!$A$2:$A$5)>0)*1))
A17: =IFERROR(INDEX(ProcessGroups!$B$2:$B$80,17-1),"") | B17: =IF($A17="","",COUNTIFS(Activities!$A$2:$A$161,INDEX(ProcessGroups!$A$2:$A$80,17-1),Activities!$C$2:$C$161,"Product owner")) | C17: =IF($A17="","",COUNTIFS(Activities!$A$2:$A$161,INDEX(ProcessGroups!$A$2:$A$80,17-1),Activities!$C$2:$C$161,"UX")) | D17: =IF($A17="","",B17+C17) | E17: =IF($A17="","",COUNTIF(Milestones!$B$2:$B$81,INDEX(ProcessGroups!$A$2:$A$80,17-1))) | F17: =IF($A17="","",SUMPRODUCT((COUNTIFS(Activities!$A$2:$A$161,INDEX(ProcessGroups!$A$2:$A$80,17-1),Activities!$B$2:$B$161,Lists!$A$2:$A$5)>0)*1))
A18: =IFERROR(INDEX(ProcessGroups!$B$2:$B$80,18-1),"") | B18: =IF($A18="","",COUNTIFS(Activities!$A$2:$A$161,INDEX(ProcessGroups!$A$2:$A$80,18-1),Activities!$C$2:$C$161,"Product owner")) | C18: =IF($A18="","",COUNTIFS(Activities!$A$2:$A$161,INDEX(ProcessGroups!$A$2:$A$80,18-1),Activities!$C$2:$C$161,"UX")) | D18: =IF($A18="","",B18+C18) | E18: =IF($A18="","",COUNTIF(Milestones!$B$2:$B$81,INDEX(ProcessGroups!$A$2:$A$80,18-1))) | F18: =IF($A18="","",SUMPRODUCT((COUNTIFS(Activities!$A$2:$A$161,INDEX(ProcessGroups!$A$2:$A$80,18-1),Activities!$B$2:$B$161,Lists!$A$2:$A$5)>0)*1))
A19: =IFERROR(INDEX(ProcessGroups!$B$2:$B$80,19-1),"") | B19: =IF($A19="","",COUNTIFS(Activities!$A$2:$A$161,INDEX(ProcessGroups!$A$2:$A$80,19-1),Activities!$C$2:$C$161,"Product owner")) | C19: =IF($A19="","",COUNTIFS(Activities!$A$2:$A$161,INDEX(ProcessGroups!$A$2:$A$80,19-1),Activities!$C$2:$C$161,"UX")) | D19: =IF($A19="","",B19+C19) | E19: =IF($A19="","",COUNTIF(Milestones!$B$2:$B$81,INDEX(ProcessGroups!$A$2:$A$80,19-1))) | F19: =IF($A19="","",SUMPRODUCT((COUNTIFS(Activities!$A$2:$A$161,INDEX(ProcessGroups!$A$2:$A$80,19-1),Activities!$B$2:$B$161,Lists!$A$2:$A$5)>0)*1))
A20: =IFERROR(INDEX(ProcessGroups!$B$2:$B$80,20-1),"") | B20: =IF($A20="","",COUNTIFS(Activities!$A$2:$A$161,INDEX(ProcessGroups!$A$2:$A$80,20-1),Activities!$C$2:$C$161,"Product owner")) | C20: =IF($A20="","",COUNTIFS(Activities!$A$2:$A$161,INDEX(ProcessGroups!$A$2:$A$80,20-1),Activities!$C$2:$C$161,"UX")) | D20: =IF($A20="","",B20+C20) | E20: =IF($A20="","",COUNTIF(Milestones!$B$2:$B$81,INDEX(ProcessGroups!$A$2:$A$80,20-1))) | F20: =IF($A20="","",SUMPRODUCT((COUNTIFS(Activities!$A$2:$A$161,INDEX(ProcessGroups!$A$2:$A$80,20-1),Activities!$B$2:$B$161,Lists!$A$2:$A$5)>0)*1))
A21: =IFERROR(INDEX(ProcessGroups!$B$2:$B$80,21-1),"") | B21: =IF($A21="","",COUNTIFS(Activities!$A$2:$A$161,INDEX(ProcessGroups!$A$2:$A$80,21-1),Activities!$C$2:$C$161,"Product owner")) | C21: =IF($A21="","",COUNTIFS(Activities!$A$2:$A$161,INDEX(ProcessGroups!$A$2:$A$80,21-1),Activities!$C$2:$C$161,"UX")) | D21: =IF($A21="","",B21+C21) | E21: =IF($A21="","",COUNTIF(Milestones!$B$2:$B$81,INDEX(ProcessGroups!$A$2:$A$80,21-1))) | F21: =IF($A21="","",SUMPRODUCT((COUNTIFS(Activities!$A$2:$A$161,INDEX(ProcessGroups!$A$2:$A$80,21-1),Activities!$B$2:$B$161,Lists!$A$2:$A$5)>0)*1))
A22: =IFERROR(INDEX(ProcessGroups!$B$2:$B$80,22-1),"") | B22: =IF($A22="","",COUNTIFS(Activities!$A$2:$A$161,INDEX(ProcessGroups!$A$2:$A$80,22-1),Activities!$C$2:$C$161,"Product owner")) | C22: =IF($A22="","",COUNTIFS(Activities!$A$2:$A$161,INDEX(ProcessGroups!$A$2:$A$80,22-1),Activities!$C$2:$C$161,"UX")) | D22: =IF($A22="","",B22+C22) | E22: =IF($A22="","",COUNTIF(Milestones!$B$2:$B$81,INDEX(ProcessGroups!$A$2:$A$80,22-1))) | F22: =IF($A22="","",SUMPRODUCT((COUNTIFS(Activities!$A$2:$A$161,INDEX(ProcessGroups!$A$2:$A$80,22-1),Activities!$B$2:$B$161,Lists!$A$2:$A$5)>0)*1))
A23: =IFERROR(INDEX(ProcessGroups!$B$2:$B$80,23-1),"") | B23: =IF($A23="","",COUNTIFS(Activities!$A$2:$A$161,INDEX(ProcessGroups!$A$2:$A$80,23-1),Activities!$C$2:$C$161,"Product owner")) | C23: =IF($A23="","",COUNTIFS(Activities!$A$2:$A$161,INDEX(ProcessGroups!$A$2:$A$80,23-1),Activities!$C$2:$C$161,"UX")) | D23: =IF($A23="","",B23+C23) | E23: =IF($A23="","",COUNTIF(Milestones!$B$2:$B$81,INDEX(ProcessGroups!$A$2:$A$80,23-1))) | F23: =IF($A23="","",SUMPRODUCT((COUNTIFS(Activities!$A$2:$A$161,INDEX(ProcessGroups!$A$2:$A$80,23-1),Activities!$B$2:$B$161,Lists!$A$2:$A$5)>0)*1))
A24: =IFERROR(INDEX(ProcessGroups!$B$2:$B$80,24-1),"") | B24: =IF($A24="","",COUNTIFS(Activities!$A$2:$A$161,INDEX(ProcessGroups!$A$2:$A$80,24-1),Activities!$C$2:$C$161,"Product owner")) | C24: =IF($A24="","",COUNTIFS(Activities!$A$2:$A$161,INDEX(ProcessGroups!$A$2:$A$80,24-1),Activities!$C$2:$C$161,"UX")) | D24: =IF($A24="","",B24+C24) | E24: =IF($A24="","",COUNTIF(Milestones!$B$2:$B$81,INDEX(ProcessGroups!$A$2:$A$80,24-1))) | F24: =IF($A24="","",SUMPRODUCT((COUNTIFS(Activities!$A$2:$A$161,INDEX(ProcessGroups!$A$2:$A$80,24-1),Activities!$B$2:$B$161,Lists!$A$2:$A$5)>0)*1))
A25: =IFERROR(INDEX(ProcessGroups!$B$2:$B$80,25-1),"") | B25: =IF($A25="","",COUNTIFS(Activities!$A$2:$A$161,INDEX(ProcessGroups!$A$2:$A$80,25-1),Activities!$C$2:$C$161,"Product owner")) | C25: =IF($A25="","",COUNTIFS(Activities!$A$2:$A$161,INDEX(ProcessGroups!$A$2:$A$80,25-1),Activities!$C$2:$C$161,"UX")) | D25: =IF($A25="","",B25+C25) | E25: =IF($A25="","",COUNTIF(Milestones!$B$2:$B$81,INDEX(ProcessGroups!$A$2:$A$80,25-1))) | F25: =IF($A25="","",SUMPRODUCT((COUNTIFS(Activities!$A$2:$A$161,INDEX(ProcessGroups!$A$2:$A$80,25-1),Activities!$B$2:$B$161,Lists!$A$2:$A$5)>0)*1))
A26: =IFERROR(INDEX(ProcessGroups!$B$2:$B$80,26-1),"") | B26: =IF($A26="","",COUNTIFS(Activities!$A$2:$A$161,INDEX(ProcessGroups!$A$2:$A$80,26-1),Activities!$C$2:$C$161,"Product owner")) | C26: =IF($A26="","",COUNTIFS(Activities!$A$2:$A$161,INDEX(ProcessGroups!$A$2:$A$80,26-1),Activities!$C$2:$C$161,"UX")) | D26: =IF($A26="","",B26+C26) | E26: =IF($A26="","",COUNTIF(Milestones!$B$2:$B$81,INDEX(ProcessGroups!$A$2:$A$80,26-1))) | F26: =IF($A26="","",SUMPRODUCT((COUNTIFS(Activities!$A$2:$A$161,INDEX(ProcessGroups!$A$2:$A$80,26-1),Activities!$B$2:$B$161,Lists!$A$2:$A$5)>0)*1))
A27: =IFERROR(INDEX(ProcessGroups!$B$2:$B$80,27-1),"") | B27: =IF($A27="","",COUNTIFS(Activities!$A$2:$A$161,INDEX(ProcessGroups!$A$2:$A$80,27-1),Activities!$C$2:$C$161,"Product owner")) | C27: =IF($A27="","",COUNTIFS(Activities!$A$2:$A$161,INDEX(ProcessGroups!$A$2:$A$80,27-1),Activities!$C$2:$C$161,"UX")) | D27: =IF($A27="","",B27+C27) | E27: =IF($A27="","",COUNTIF(Milestones!$B$2:$B$81,INDEX(ProcessGroups!$A$2:$A$80,27-1))) | F27: =IF($A27="","",SUMPRODUCT((COUNTIFS(Activities!$A$2:$A$161,INDEX(ProcessGroups!$A$2:$A$80,27-1),Activities!$B$2:$B$161,Lists!$A$2:$A$5)>0)*1))
A28: =IFERROR(INDEX(ProcessGroups!$B$2:$B$80,28-1),"") | B28: =IF($A28="","",COUNTIFS(Activities!$A$2:$A$161,INDEX(ProcessGroups!$A$2:$A$80,28-1),Activities!$C$2:$C$161,"Product owner")) | C28: =IF($A28="","",COUNTIFS(Activities!$A$2:$A$161,INDEX(ProcessGroups!$A$2:$A$80,28-1),Activities!$C$2:$C$161,"UX")) | D28: =IF($A28="","",B28+C28) | E28: =IF($A28="","",COUNTIF(Milestones!$B$2:$B$81,INDEX(ProcessGroups!$A$2:$A$80,28-1))) | F28: =IF($A28="","",SUMPRODUCT((COUNTIFS(Activities!$A$2:$A$161,INDEX(ProcessGroups!$A$2:$A$80,28-1),Activities!$B$2:$B$161,Lists!$A$2:$A$5)>0)*1))
A29: =IFERROR(INDEX(ProcessGroups!$B$2:$B$80,29-1),"") | B29: =IF($A29="","",COUNTIFS(Activities!$A$2:$A$161,INDEX(ProcessGroups!$A$2:$A$80,29-1),Activities!$C$2:$C$161,"Product owner")) | C29: =IF($A29="","",COUNTIFS(Activities!$A$2:$A$161,INDEX(ProcessGroups!$A$2:$A$80,29-1),Activities!$C$2:$C$161,"UX")) | D29: =IF($A29="","",B29+C29) | E29: =IF($A29="","",COUNTIF(Milestones!$B$2:$B$81,INDEX(ProcessGroups!$A$2:$A$80,29-1))) | F29: =IF($A29="","",SUMPRODUCT((COUNTIFS(Activities!$A$2:$A$161,INDEX(ProcessGroups!$A$2:$A$80,29-1),Activities!$B$2:$B$161,Lists!$A$2:$A$5)>0)*1))
A30: =IFERROR(INDEX(ProcessGroups!$B$2:$B$80,30-1),"") | B30: =IF($A30="","",COUNTIFS(Activities!$A$2:$A$161,INDEX(ProcessGroups!$A$2:$A$80,30-1),Activities!$C$2:$C$161,"Product owner")) | C30: =IF($A30="","",COUNTIFS(Activities!$A$2:$A$161,INDEX(ProcessGroups!$A$2:$A$80,30-1),Activities!$C$2:$C$161,"UX")) | D30: =IF($A30="","",B30+C30) | E30: =IF($A30="","",COUNTIF(Milestones!$B$2:$B$81,INDEX(ProcessGroups!$A$2:$A$80,30-1))) | F30: =IF($A30="","",SUMPRODUCT((COUNTIFS(Activities!$A$2:$A$161,INDEX(ProcessGroups!$A$2:$A$80,30-1),Activities!$B$2:$B$161,Lists!$A$2:$A$5)>0)*1))
A31: =IFERROR(INDEX(ProcessGroups!$B$2:$B$80,31-1),"") | B31: =IF($A31="","",COUNTIFS(Activities!$A$2:$A$161,INDEX(ProcessGroups!$A$2:$A$80,31-1),Activities!$C$2:$C$161,"Product owner")) | C31: =IF($A31="","",COUNTIFS(Activities!$A$2:$A$161,INDEX(ProcessGroups!$A$2:$A$80,31-1),Activities!$C$2:$C$161,"UX")) | D31: =IF($A31="","",B31+C31) | E31: =IF($A31="","",COUNTIF(Milestones!$B$2:$B$81,INDEX(ProcessGroups!$A$2:$A$80,31-1))) | F31: =IF($A31="","",SUMPRODUCT((COUNTIFS(Activities!$A$2:$A$161,INDEX(ProcessGroups!$A$2:$A$80,31-1),Activities!$B$2:$B$161,Lists!$A$2:$A$5)>0)*1))
A32: =IFERROR(INDEX(ProcessGroups!$B$2:$B$80,32-1),"") | B32: =IF($A32="","",COUNTIFS(Activities!$A$2:$A$161,INDEX(ProcessGroups!$A$2:$A$80,32-1),Activities!$C$2:$C$161,"Product owner")) | C32: =IF($A32="","",COUNTIFS(Activities!$A$2:$A$161,INDEX(ProcessGroups!$A$2:$A$80,32-1),Activities!$C$2:$C$161,"UX")) | D32: =IF($A32="","",B32+C32) | E32: =IF($A32="","",COUNTIF(Milestones!$B$2:$B$81,INDEX(ProcessGroups!$A$2:$A$80,32-1))) | F32: =IF($A32="","",SUMPRODUCT((COUNTIFS(Activities!$A$2:$A$161,INDEX(ProcessGroups!$A$2:$A$80,32-1),Activities!$B$2:$B$161,Lists!$A$2:$A$5)>0)*1))
A33: =IFERROR(INDEX(ProcessGroups!$B$2:$B$80,33-1),"") | B33: =IF($A33="","",COUNTIFS(Activities!$A$2:$A$161,INDEX(ProcessGroups!$A$2:$A$80,33-1),Activities!$C$2:$C$161,"Product owner")) | C33: =IF($A33="","",COUNTIFS(Activities!$A$2:$A$161,INDEX(ProcessGroups!$A$2:$A$80,33-1),Activities!$C$2:$C$161,"UX")) | D33: =IF($A33="","",B33+C33) | E33: =IF($A33="","",COUNTIF(Milestones!$B$2:$B$81,INDEX(ProcessGroups!$A$2:$A$80,33-1))) | F33: =IF($A33="","",SUMPRODUCT((COUNTIFS(Activities!$A$2:$A$161,INDEX(ProcessGroups!$A$2:$A$80,33-1),Activities!$B$2:$B$161,Lists!$A$2:$A$5)>0)*1))
A34: =IFERROR(INDEX(ProcessGroups!$B$2:$B$80,34-1),"") | B34: =IF($A34="","",COUNTIFS(Activities!$A$2:$A$161,INDEX(ProcessGroups!$A$2:$A$80,34-1),Activities!$C$2:$C$161,"Product owner")) | C34: =IF($A34="","",COUNTIFS(Activities!$A$2:$A$161,INDEX(ProcessGroups!$A$2:$A$80,34-1),Activities!$C$2:$C$161,"UX")) | D34: =IF($A34="","",B34+C34) | E34: =IF($A34="","",COUNTIF(Milestones!$B$2:$B$81,INDEX(ProcessGroups!$A$2:$A$80,34-1))) | F34: =IF($A34="","",SUMPRODUCT((COUNTIFS(Activities!$A$2:$A$161,INDEX(ProcessGroups!$A$2:$A$80,34-1),Activities!$B$2:$B$161,Lists!$A$2:$A$5)>0)*1))
A35: =IFERROR(INDEX(ProcessGroups!$B$2:$B$80,35-1),"") | B35: =IF($A35="","",COUNTIFS(Activities!$A$2:$A$161,INDEX(ProcessGroups!$A$2:$A$80,35-1),Activities!$C$2:$C$161,"Product owner")) | C35: =IF($A35="","",COUNTIFS(Activities!$A$2:$A$161,INDEX(ProcessGroups!$A$2:$A$80,35-1),Activities!$C$2:$C$161,"UX")) | D35: =IF($A35="","",B35+C35) | E35: =IF($A35="","",COUNTIF(Milestones!$B$2:$B$81,INDEX(ProcessGroups!$A$2:$A$80,35-1))) | F35: =IF($A35="","",SUMPRODUCT((COUNTIFS(Activities!$A$2:$A$161,INDEX(ProcessGroups!$A$2:$A$80,35-1),Activities!$B$2:$B$161,Lists!$A$2:$A$5)>0)*1))
A36: =IFERROR(INDEX(ProcessGroups!$B$2:$B$80,36-1),"") | B36: =IF($A36="","",COUNTIFS(Activities!$A$2:$A$161,INDEX(ProcessGroups!$A$2:$A$80,36-1),Activities!$C$2:$C$161,"Product owner")) | C36: =IF($A36="","",COUNTIFS(Activities!$A$2:$A$161,INDEX(ProcessGroups!$A$2:$A$80,36-1),Activities!$C$2:$C$161,"UX")) | D36: =IF($A36="","",B36+C36) | E36: =IF($A36="","",COUNTIF(Milestones!$B$2:$B$81,INDEX(ProcessGroups!$A$2:$A$80,36-1))) | F36: =IF($A36="","",SUMPRODUCT((COUNTIFS(Activities!$A$2:$A$161,INDEX(ProcessGroups!$A$2:$A$80,36-1),Activities!$B$2:$B$161,Lists!$A$2:$A$5)>0)*1))
A37: =IFERROR(INDEX(ProcessGroups!$B$2:$B$80,37-1),"") | B37: =IF($A37="","",COUNTIFS(Activities!$A$2:$A$161,INDEX(ProcessGroups!$A$2:$A$80,37-1),Activities!$C$2:$C$161,"Product owner")) | C37: =IF($A37="","",COUNTIFS(Activities!$A$2:$A$161,INDEX(ProcessGroups!$A$2:$A$80,37-1),Activities!$C$2:$C$161,"UX")) | D37: =IF($A37="","",B37+C37) | E37: =IF($A37="","",COUNTIF(Milestones!$B$2:$B$81,INDEX(ProcessGroups!$A$2:$A$80,37-1))) | F37: =IF($A37="","",SUMPRODUCT((COUNTIFS(Activities!$A$2:$A$161,INDEX(ProcessGroups!$A$2:$A$80,37-1),Activities!$B$2:$B$161,Lists!$A$2:$A$5)>0)*1))
A38: =IFERROR(INDEX(ProcessGroups!$B$2:$B$80,38-1),"") | B38: =IF($A38="","",COUNTIFS(Activities!$A$2:$A$161,INDEX(ProcessGroups!$A$2:$A$80,38-1),Activities!$C$2:$C$161,"Product owner")) | C38: =IF($A38="","",COUNTIFS(Activities!$A$2:$A$161,INDEX(ProcessGroups!$A$2:$A$80,38-1),Activities!$C$2:$C$161,"UX")) | D38: =IF($A38="","",B38+C38) | E38: =IF($A38="","",COUNTIF(Milestones!$B$2:$B$81,INDEX(ProcessGroups!$A$2:$A$80,38-1))) | F38: =IF($A38="","",SUMPRODUCT((COUNTIFS(Activities!$A$2:$A$161,INDEX(ProcessGroups!$A$2:$A$80,38-1),Activities!$B$2:$B$161,Lists!$A$2:$A$5)>0)*1))
A39: =IFERROR(INDEX(ProcessGroups!$B$2:$B$80,39-1),"") | B39: =IF($A39="","",COUNTIFS(Activities!$A$2:$A$161,INDEX(ProcessGroups!$A$2:$A$80,39-1),Activities!$C$2:$C$161,"Product owner")) | C39: =IF($A39="","",COUNTIFS(Activities!$A$2:$A$161,INDEX(ProcessGroups!$A$2:$A$80,39-1),Activities!$C$2:$C$161,"UX")) | D39: =IF($A39="","",B39+C39) | E39: =IF($A39="","",COUNTIF(Milestones!$B$2:$B$81,INDEX(ProcessGroups!$A$2:$A$80,39-1))) | F39: =IF($A39="","",SUMPRODUCT((COUNTIFS(Activities!$A$2:$A$161,INDEX(ProcessGroups!$A$2:$A$80,39-1),Activities!$B$2:$B$161,Lists!$A$2:$A$5)>0)*1))
A40: =IFERROR(INDEX(ProcessGroups!$B$2:$B$80,40-1),"") | B40: =IF($A40="","",COUNTIFS(Activities!$A$2:$A$161,INDEX(ProcessGroups!$A$2:$A$80,40-1),Activities!$C$2:$C$161,"Product owner")) | C40: =IF($A40="","",COUNTIFS(Activities!$A$2:$A$161,INDEX(ProcessGroups!$A$2:$A$80,40-1),Activities!$C$2:$C$161,"UX")) | D40: =IF($A40="","",B40+C40) | E40: =IF($A40="","",COUNTIF(Milestones!$B$2:$B$81,INDEX(ProcessGroups!$A$2:$A$80,40-1))) | F40: =IF($A40="","",SUMPRODUCT((COUNTIFS(Activities!$A$2:$A$161,INDEX(ProcessGroups!$A$2:$A$80,40-1),Activities!$B$2:$B$161,Lists!$A$2:$A$5)>0)*1))
...
